const [error1] = tryCatch(fn, a);
const [error2] = await tryToCatch(fn, a);
